<!-- Copyright 2021 DeepMind Technologies Limited

     Licensed under the Apache License, Version 2.0 (the "License");
     you may not use this file except in compliance with the License.
     You may obtain a copy of the License at

         http://www.apache.org/licenses/LICENSE-2.0

     Unless required by applicable law or agreed to in writing, software
     distributed under the License is distributed on an "AS IS" BASIS,
     WITHOUT WARRANTIES OR CONDITIONS OF ANY KIND, either express or implied.
     See the License for the specific language governing permissions and
     limitations under the License.
-->

<mujoco model="Humanoid">
  <option timestep="0.005"/>

  <visual>
    <map force="0.1" zfar="30"/>
    <rgba haze="0.15 0.25 0.35 1"/>
    <global offwidth="2560" offheight="1440" elevation="-20" azimuth="120"/>
  </visual>

  <statistic center="0 0 0.7"/>

  <asset>
    <texture type="skybox" builtin="gradient" rgb1=".3 .5 .7" rgb2="0 0 0" width="32" height="512"/>
    <texture name="body" type="cube" builtin="flat" mark="cross" width="128" height="128" rgb1="0.8 0.6 0.4" rgb2="0.8 0.6 0.4" markrgb="1 1 1"/>
    <material name="body" texture="body" texuniform="true" rgba="0.8 0.6 .4 1"/>
    <texture name="grid" type="2d" builtin="checker" width="512" height="512" rgb1=".1 .2 .3" rgb2=".2 .3 .4"/>
    <material name="grid" texture="grid" texrepeat="1 1" texuniform="true" reflectance=".2"/>
  </asset>

  <default>
    <motor ctrlrange="-1 1" ctrllimited="true"/>
    <default class="body">

      <!-- geoms -->
      <geom type="capsule" condim="1" friction=".7" solimp=".9 .99 .003" solref=".015 1" material="body" group="1"/>
      <default class="thigh">
        <geom size=".06"/>
      </default>
      <default class="shin">
        <geom fromto="0 0 0 0 0 -.3"  size=".049"/>
      </default>
      <default class="foot">
        <geom size=".027"/>
        <default class="foot1">
          <geom fromto="-.07 -.01 0 .14 -.03 0"/>
        </default>
        <default class="foot2">
          <geom fromto="-.07 .01 0 .14  .03 0"/>
        </default>
      </default>
      <default class="arm_upper">
        <geom size=".04"/>
      </default>
      <default class="arm_lower">
        <geom size=".031"/>
      </default>
      <default class="hand">
        <geom type="sphere" size=".04"/>
      </default>

      <!-- joints -->
      <joint type="hinge" damping=".2" stiffness="1" armature=".01" limited="true" solimplimit="0 .99 .01"/>
      <default class="joint_big">
        <joint damping="5" stiffness="5"/>
        <default class="hip_x">
          <joint range="-30 10"/>
        </default>
        <default class="hip_z">
          <joint range="-60 35"/>
        </default>
        <default class="hip_y">
          <joint axis="0 1 0" range="-150 20"/>
        </default>
        <default class="joint_big_stiff">
          <joint stiffness="10"/>
        </default>
      </default>
      <default class="knee">
        <joint pos="0 0 .02" axis="0 -1 0" range="-160 2"/>
      </default>
      <default class="ankle">
        <joint range="-50 50"/>
        <default class="ankle_y">
          <joint pos="0 0 .08" axis="0 1 0" stiffness="3"/>
        </default>
        <default class="ankle_x">
          <joint pos="0 0 .04" stiffness="1"/>
        </default>
      </default>
    </default>
  </default>

  <worldbody>
    <geom name="floor" size="0 0 .05" type="plane" material="grid" condim="3"/>
    <light name="spotlight" mode="targetbodycom" target="torso" diffuse=".8 .8 .8" specular="0.3 0.3 0.3" pos="0 -6 4" cutoff="30"/>
    <light name="top" pos="0 0 2" mode="trackcom"/>


    <body name="torso" pos="0 0 1.282" childclass="body">
      <camera name="back" pos="-3 0 1" xyaxes="0 -1 0 1 0 2" mode="trackcom"/>
      <camera name="side" pos="0 -3 1" xyaxes="1 0 0 0 1 2" mode="trackcom"/>
      <freejoint name="root"/>
      <geom name="torso" fromto="0 -.07 0 0 .07 0" size=".07"/>
      <geom name="waist_upper" fromto="-.01 -.06 -.12 -.01 .06 -.12" size=".06"/>
      <body name="head" pos="0 0 .19">
        <geom name="head" type="sphere" size=".09"/>
        <camera name="egocentric" pos=".09 0 0" xyaxes="0 -1 0 .1 0 1" fovy="80"/>
      </body>
        <site name="x6" pos="0.1 0 0" size="0.02" rgba="0 1 0 1"/>
        <site name="x7" pos="-0.1 0 0" size="0.02" rgba="0 1 0 1"/>


      <body name="waist_lower" pos="-.01 0 -.26">
        <geom name="waist_lower" fromto="0 -.06 0 0 .06 0" size=".06"/>

        <joint name="abdomen_z" pos="0 0 .065" axis="0 0 1" range="-45 45" class="joint_big_stiff"/>
        <joint name="abdomen_y" pos="0 0 .065" axis="0 1 0" range="-75 30" class="joint_big"/>
        <site name="x5" pos="0 0 0" size="0.02" rgba="0 1 0 1"/>


        <body name="pelvis" pos="0 0 -.165">



          <site name="x1" pos="0 0 -0.1" size="0.02" rgba="0 1 0 1"/>
          <site name="x2" pos="0 0.25 -0.1" size="0.02" rgba="0 1 0 1"/>
          <site name="x2_R" pos="0 -0.25 -0.1" size="0.02" rgba="0 1 0 1"/>
          <site name="x3_R" pos="0 -0.1 0.1" size="0.02" rgba="0 1 0 1"/>
          <site name="x3" pos="0 0.1 0.1" size="0.02" rgba="0 1 0 1"/>


          <joint name="abdomen_x" pos="0 0 .1" axis="1 0 0" range="-35 35" class="joint_big"/>
          <geom name="butt" fromto="-.02 -.07 0 -.02 .07 0" size=".09"/>

          <body name="pelvis_left" pos="0 0.1 -0.05">
              <geom name="pelvis_left" type="sphere" size="0.065" rgba="0 0 255 1" group="1"/>

              <site name="ss_7" pos="-0.08 0 0"  size="0.005" rgba="1 0 1 1"/>
              <site name="ss_8" pos="0.08 0 0"  size="0.005" rgba="1 0 1 1"/>

          </body>

          <body name="pelvis_right" pos="0 -0.1 -0.05">
              <geom name="pelvis_right" type="sphere" size="0.065" rgba="0 0 255 1" group="1"/>

              <site name="ss_7_R" pos="-0.08 0 0"  size="0.005" rgba="1 0 1 1"/>
              <site name="ss_8_R" pos="0.08 0 0"  size="0.005" rgba="1 0 1 1"/>

          </body>

          <body name="thigh_right" pos="0 -.1 -.04">

            <site name="upper_leg_right" pos="0 -0.06 -0.2" size="0.02" rgba="0 1 0 1"/>
            <site name="upper_leg_right_1" pos="0 0.06 -0.2" size="0.02" rgba="0 1 0 1"/>
            <site name="upper_leg_right_2" pos="0.06 0 -0.2" size="0.02" rgba="0 1 0 1"/>
            <site name="upper_leg_right_3" pos="-0.06 0 -0.1" size="0.02" rgba="0 1 0 1"/>

            <joint name="hip_x_right" axis="1 0 0" class="hip_x"/>
            <joint name="hip_z_right" axis="0 0 1" class="hip_z"/>
            <joint name="hip_y_right" class="hip_y"/>
            <geom name="thigh_right" fromto="0 0 0 0 .01 -.34" class="thigh"/>

            <body name="knee_right" pos="0 0.01 -0.35">
              <geom name="knee_right" type="sphere" size="0.06" rgba="0 0 255 1" group="1"/>

              <site name="ss_5_R" pos="-0.08 0 0"  size="0.005" rgba="1 0 1 1"/>
              <site name="ss_6_R" pos="0.08 0 0"  size="0.005" rgba="1 0 1 1"/>

            </body>

            <body name="shin_right" pos="0 .01 -.4">


              <site name="calf_front_site_right" pos="-0.05 0 -0.1"  size="0.005" rgba="1 0 1 1"/>
              <site name="calf_back_site_right" pos="0.05 0 -0.1"  size="0.005" rgba="1 0 1 1"/>
              <site name="calf_side_site_right_1" pos="0 -0.06 -0.25"  size="0.005" rgba="1 0 1 1"/>
              <site name="calf_side_site_right_2" pos="0 0.06 -0.25"  size="0.005" rgba="1 0 1 1"/>

              <joint name="knee_right" class="knee"/>
              <geom name="shin_right" class="shin"/>

              <body name="ankle_right" pos="0 0 -0.35">
                <geom name="ankle_right" type="sphere" size="0.04" rgba="0 0 255 1" group="1"/>

                <site name="ss_1_R" pos="-0.08 0 0"  size="0.005" rgba="1 0 1 1"/>
                <site name="ss_2_R" pos="0.08 0 0"  size="0.005" rgba="1 0 1 1"/>
                <site name="ss_3_R" pos="0 0.05 0"  size="0.005" rgba="1 0 1 1"/>
                <site name="ss_4_R" pos="0 -0.05 0"  size="0.005" rgba="1 0 1 1"/>        

              </body>

              <body name="foot_right" pos="0 0 -.39">

                <site name="achilles_front_site_right"   size="0.005" pos="-0.08 0 0.01" rgba="1 0 0 1"/>
                <site name="achilles_back_site_right"   size="0.005" pos="0.08 0 0.01" rgba="1 0 0 1"/>

                <site name="achilles_side_site_right_1"   size="0.005" pos="0 -0.05 0.01" rgba="1 0 0 1"/>
                <site name="achilles_side_site_right_2"  size="0.005" pos="0 0.05 0.01" rgba="1 0 0 1"/>

                <joint name="ankle_y_right" class="ankle_y"/>
                <joint name="ankle_x_right" class="ankle_x" axis="1 0 .5"/>
                <geom name="foot1_right" class="foot1"/>
                <geom name="foot2_right" class="foot2"/>
              </body>
            </body>
          </body>



          <body name="thigh_left" pos="0 .1 -.04">

            <site name="upper_leg_left" pos="0 -0.06 -0.2" size="0.02" rgba="0 1 0 1"/>
            <site name="upper_leg_left_1" pos="0 0.06 -0.2" size="0.02" rgba="0 1 0 1"/>
            <site name="upper_leg_left_2" pos="0.06 0 -0.2" size="0.02" rgba="0 1 0 1"/>
            <site name="upper_leg_left_3" pos="-0.06 0 -0.1" size="0.02" rgba="0 1 0 1"/>

            <joint name="hip_x_left" axis="-1 0 0" class="hip_x"/>
            <joint name="hip_z_left" axis="0 0 -1" class="hip_z"/>
            <joint name="hip_y_left" class="hip_y"/>
            <geom name="thigh_left" fromto="0 0 0 0 -.01 -.34" class="thigh"/>

            <body name="knee_left" pos="0 -0.01 -0.35">
              <geom name="knee_left" type="sphere" size="0.06" rgba="0 0 255 1" group="1"/>

              <site name="ss_5" pos="-0.08 0 0"  size="0.005" rgba="1 0 1 1"/>
              <site name="ss_6" pos="0.08 0 0"  size="0.005" rgba="1 0 1 1"/>

            </body>

            <body name="shin_left" pos="0 -.01 -.4">

              <site name="calf_front_site_left" pos="-0.05 0 -0.1"  size="0.005" rgba="1 0 1 1"/>
              <site name="calf_back_site_left" pos="0.05 0 -0.1"  size="0.005" rgba="1 0 1 1"/>
              <site name="calf_side_site_left_1" pos="0 -0.06 -0.25"  size="0.005" rgba="1 0 1 1"/>
              <site name="calf_side_site_left_2" pos="0 0.06 -0.25"  size="0.005" rgba="1 0 1 1"/>

              <joint name="knee_left" class="knee"/>
              <geom name="shin_left" fromto="0 0 0 0 0 -.3" class="shin"/>


              <body name="ankle_left" pos="0 0 -0.35">
                <geom name="ankle_left" type="sphere" size="0.04" rgba="0 0 255 1" group="1"/>

                <site name="ss_1" pos="-0.08 0 0"  size="0.005" rgba="1 0 1 1"/>
                <site name="ss_2" pos="0.08 0 0"  size="0.005" rgba="1 0 1 1"/>
                <site name="ss_3" pos="0 0.05 0"  size="0.005" rgba="1 0 1 1"/>
                <site name="ss_4" pos="0 -0.05 0"  size="0.005" rgba="1 0 1 1"/>        

              </body>


              <body name="foot_left" pos="0 0 -.39">

                <site name="achilles_front_site_left"   size="0.005" pos="-0.08 0 0.01" rgba="1 0 0 1"/>
                <site name="achilles_back_site_left"   size="0.005" pos="0.08 0 0.01" rgba="1 0 0 1"/>

                <site name="achilles_side_site_left_1"   size="0.005" pos="0 -0.05 0.01" rgba="1 0 0 1"/>
                <site name="achilles_side_site_left_2"  size="0.005" pos="0 0.05 0.01" rgba="1 0 0 1"/>

                <joint name="ankle_y_left" class="ankle_y"/>
                <joint name="ankle_x_left" class="ankle_x" axis="-1 0 -.5"/>
                <geom name="foot1_left" class="foot1"/>
                <geom name="foot2_left" class="foot2"/>
              </body>


            </body>
          </body>

        </body>

      </body>


    </body>
  </worldbody>

  <contact>
    <exclude body1="waist_lower" body2="thigh_right"/>
    <exclude body1="waist_lower" body2="thigh_left"/>
  </contact>

  <tendon>


    <!-- <fixed name="hamstring_right" limited="true" range="-0.3 2">
      <joint joint="hip_y_right" coef=".5"/>
      <joint joint="knee_right" coef="-.5"/>
    </fixed>
    <fixed name="hamstring_left" limited="true" range="-0.3 2">
      <joint joint="hip_y_left" coef=".5"/>  <tendon>
    <fixed name="hamstring_right" limited="true" range="-0.3 2">
      <joint joint="hip_y_right" coef=".5"/>
      <joint joint="knee_right" coef="-.5"/>
    </fixed>
    <fixed name="hamstring_left" limited="true" range="-0.3 2">
      <joint joint="hip_y_left" coef=".5"/>
      <joint joint="knee_left" coef="-.5"/>
    </fixed>
  </tendon>
    </fixed> -->


    <spatial name="ab_F" width="0.005" rgba=".4 .6 .4 1" group="1">
        <site site="x1"/>
        <site site="x6"/>
    </spatial>

    <spatial name="ab_B" width="0.005" rgba=".4 .6 .4 1" group="1">
        <site site="x1"/>
        <site site="x7"/>
    </spatial>


    <spatial name="ab_R" width="0.005" rgba=".4 .6 .4 1" group="1">
        <site site="x5"/>
        <site site="x3_R"/>
    </spatial>

    <spatial name="leg_back_R" width="0.005" rgba=".4 .6 .4 1" group="1">
        <site site="x3_R"/>
        <geom geom="pelvis_right" sidesite="ss_7_R"/>
        <site site="upper_leg_right_3"/>
    </spatial>


    <spatial name="leg_front_R" width="0.005" rgba=".4 .6 .4 1" group="1">
        <site site="x3_R"/>
        <geom geom="pelvis_right" sidesite="ss_8_R"/>
        <site site="upper_leg_right_2"/>
    </spatial>

    <spatial name="abduc_out_R" width="0.005" rgba=".4 .6 .4 1" group="1">
        <site site="x2_R"/>
        <site site="upper_leg_right"/>
    </spatial>

    <spatial name="abduc_in_R" width="0.005" rgba=".4 .6 .4 1" group="1">
        <site site="x1"/>
        <site site="upper_leg_right_1"/>
    </spatial>

    <spatial name="hamstring_R" width="0.005" rgba=".4 .6 .4 1" group="1">
        <site site="upper_leg_right_3"/>
        <geom geom="knee_right" sidesite="ss_5_R"/>
        <site site="calf_front_site_right"/>
    </spatial>

    <spatial name="quad_R" width="0.005" rgba=".4 .6 .4 1" group="1">
        <site site="upper_leg_right_2"/>
        <geom geom="knee_right" sidesite="ss_6_R"/>
        <site site="calf_back_site_right"/>
    </spatial>


    <spatial name="front_foot_R" width="0.005" rgba=".4 .6 .4 1" group="1">
        <site site="calf_back_site_right"/>
        <geom geom="ankle_right" sidesite="ss_2_R"/>
        <site site="achilles_back_site_right"/>
    </spatial>

    <spatial name="back_foot_R" width="0.005" rgba=".4 .6 .4 1" group="1">
        <site site="calf_front_site_right"/>
        <geom geom="ankle_right" sidesite="ss_1_R"/>
        <site site="achilles_front_site_right"/>
    </spatial>

    <spatial name="side_foot_1_R" width="0.005" rgba=".4 .6 .4 1" group="1">
        <site site="calf_side_site_right_1"/>
        <geom geom="ankle_right" sidesite="ss_4_R"/>
        <site site="achilles_side_site_right_1"/>
    </spatial>

    <spatial name="side_foot_2_R" width="0.005" rgba=".4 .6 .4 1" group="1">
        <site site="calf_side_site_right_2"/>
        <geom geom="ankle_right" sidesite="ss_3_R"/>
        <site site="achilles_side_site_right_2"/>
    </spatial>


    <spatial name="ab" width="0.005" rgba=".4 .6 .4 1" group="1">
        <site site="x5"/>
        <site site="x3"/>
    </spatial>


    <spatial name="leg_back" width="0.005" rgba=".4 .6 .4 1" group="1">
        <site site="x3"/>
        <geom geom="pelvis_left" sidesite="ss_7"/>
        <site site="upper_leg_left_3"/>
    </spatial>


    <spatial name="leg_front" width="0.005" rgba=".4 .6 .4 1" group="1">
        <site site="x3"/>
        <geom geom="pelvis_left" sidesite="ss_8"/>
        <site site="upper_leg_left_2"/>
    </spatial>

    <spatial name="abduc_out" width="0.005" rgba=".4 .6 .4 1" group="1">
        <site site="x2"/>
        <site site="upper_leg_left_1"/>
    </spatial>

    <spatial name="abduc_in" width="0.005" rgba=".4 .6 .4 1" group="1">
        <site site="x1"/>
        <site site="upper_leg_left"/>
    </spatial>

    <spatial name="hamstring" width="0.005" rgba=".4 .6 .4 1" group="1">
        <site site="upper_leg_left_3"/>
        <geom geom="knee_left" sidesite="ss_5"/>
        <site site="calf_front_site_left"/>
    </spatial>

    <spatial name="quad" width="0.005" rgba=".4 .6 .4 1" group="1">
        <site site="upper_leg_left_2"/>
        <geom geom="knee_left" sidesite="ss_6"/>
        <site site="calf_back_site_left"/>
    </spatial>


    <spatial name="front_foot" width="0.005" rgba=".4 .6 .4 1" group="1">
        <site site="calf_back_site_left"/>
        <geom geom="ankle_left" sidesite="ss_2"/>
        <site site="achilles_back_site_left"/>
    </spatial>

    <spatial name="back_foot" width="0.005" rgba=".4 .6 .4 1" group="1">
        <site site="calf_front_site_left"/>
        <geom geom="ankle_left" sidesite="ss_1"/>
        <site site="achilles_front_site_left"/>
    </spatial>

    <spatial name="side_foot_1" width="0.005" rgba=".4 .6 .4 1" group="1">
        <site site="calf_side_site_left_1"/>
        <geom geom="ankle_left" sidesite="ss_4"/>
        <site site="achilles_side_site_left_1"/>
    </spatial>

    <spatial name="side_foot_2" width="0.005" rgba=".4 .6 .4 1" group="1">
        <site site="calf_side_site_left_2"/>
        <geom geom="ankle_left" sidesite="ss_3"/>
        <site site="achilles_side_site_left_2"/>
    </spatial>



  </tendon>

  <actuator>
    <!-- <motor name="abdomen_z"       gear="40"  joint="abdomen_z"/>
    <motor name="abdomen_y"       gear="40"  joint="abdomen_y"/>
    <motor name="abdomen_x"       gear="40"  joint="abdomen_x"/>
    <motor name="hip_x_right"     gear="40"  joint="hip_x_right"/>
    <motor name="hip_z_right"     gear="40"  joint="hip_z_right"/>
    <motor name="hip_y_right"     gear="120" joint="hip_y_right"/>
    <motor name="knee_right"      gear="80"  joint="knee_right"/>
    <motor name="ankle_y_right"   gear="20"  joint="ankle_y_right"/>
    <motor name="ankle_x_right"   gear="20"  joint="ankle_x_right"/>
    <motor name="hip_x_left"      gear="40"  joint="hip_x_left"/>

    <motor name="hip_y_left"      gear="120" joint="hip_y_left"/>
    <motor name="knee_left"       gear="80"  joint="knee_left"/>
    <motor name="ankle_y_left"    gear="20"  joint="ankle_y_left"/>
    <motor name="ankle_x_left"    gear="20"  joint="ankle_x_left"/> -->

    <muscle name="ab_F" tendon="ab_F" lengthrange="0 1" ctrlrange="0 1" force="750"/>

    <muscle name="ab_B" tendon="ab_B" lengthrange="0 1" ctrlrange="0 1" force="750"/>


    <muscle name="ab" tendon="ab" lengthrange="0 1" ctrlrange="0 1" force="750"/>

    <muscle name="ab_R" tendon="ab_R" lengthrange="0 1" ctrlrange="0 1" force="750"/>


    <muscle name="leg_back_R" tendon="leg_back_R" lengthrange="0 1" ctrlrange="0 1" />

    <muscle name="leg_front_R" tendon="leg_front_R" lengthrange="0 1" ctrlrange="0 1" force="400"/>

    <muscle name="abduc_out_R" tendon="abduc_out_R" lengthrange="0 1" ctrlrange="0 1"/>

    <muscle name="abduc_in_R" tendon="abduc_in_R" lengthrange="0 1" ctrlrange="0 1"/>

    <muscle name="hamstring_R" tendon="hamstring_R" lengthrange="0 1" ctrlrange="0 1"/>
    <muscle name="quad_R" tendon="quad_R" lengthrange="0 1" ctrlrange="0 1"/>

    <muscle name="back_foot_R" tendon="back_foot_R" lengthrange="0 1" ctrlrange="0 1"/>
    <muscle name="front_foot_R" tendon="front_foot_R" lengthrange="0 1" ctrlrange="0 1"/>
    <muscle name="side_foot_1_R" tendon="side_foot_1_R" lengthrange="0 1" ctrlrange="0 1"/>  
    <muscle name="side_foot_2_R" tendon="side_foot_2_R" lengthrange="0 1" ctrlrange="0 1"/>  




    <muscle name="leg_back" tendon="leg_back" lengthrange="0 1" ctrlrange="0 1" />

    <muscle name="leg_front" tendon="leg_front" lengthrange="0 1" ctrlrange="0 1" force="400"/>

    <muscle name="abduc_out" tendon="abduc_out" lengthrange="0 1" ctrlrange="0 1"/>

    <muscle name="abduc_in" tendon="abduc_in" lengthrange="0 1" ctrlrange="0 1"/>

    <muscle name="hamstring" tendon="hamstring" lengthrange="0 1" ctrlrange="0 1"/>
    <muscle name="quad" tendon="quad" lengthrange="0 1" ctrlrange="0 1"/>

    <muscle name="back_foot" tendon="back_foot" lengthrange="0 1" ctrlrange="0 1"/>
    <muscle name="front_foot" tendon="front_foot" lengthrange="0 1" ctrlrange="0 1"/>
    <muscle name="side_foot_1" tendon="side_foot_1" lengthrange="0 1" ctrlrange="0 1"/>  
    <muscle name="side_foot_2" tendon="side_foot_2" lengthrange="0 1" ctrlrange="0 1"/>  
  </actuator>

  <!-- <keyframe> -->
    <!--
    The values below are split into rows for readibility:
      torso position
      torso orientation
      spinal
      right leg
      left leg
      arms
    -->
    <!-- <key name="squat"
         qpos="0 0 0.596
               0.988015 0 0.154359 0
               0 0.4 0
               -0.25 -0.5 -2.5 -2.65 -0.8 0.56
               -0.25 -0.5 -2.5 -2.65 -0.8 0.56
               "/>
    <key name="stand_on_left_leg"
         qpos="0 0 1.21948
               0.971588 -0.179973 0.135318 -0.0729076
               -0.0516 -0.202 0.23
               -0.24 -0.007 -0.34 -1.76 -0.466 -0.0415
               -0.08 -0.01 -0.37 -0.685 -0.35 -0.09
               "/>
    <key name="prone"
         qpos="0.4 0 0.0757706
               0.7325 0 0.680767 0
               0 0.0729 0
               0.0077 0.0019 -0.026 -0.351 -0.27 0
               0.0077 0.0019 -0.026 -0.351 -0.27 0
        
               "/>
    <key name="supine"
         qpos="-0.4 0 0.08122
               0.722788 0 -0.69107 0
               0 -0.25 0
               0.0182 0.0142 0.3 0.042 -0.44 -0.02
               0.0182 0.0142 0.3 0.042 -0.44 -0.02
            
               "/>
  </keyframe> -->
</mujoco>